Traceback (most recent call last):
  File "D:\Repositories\adobe\user-sync-fork\dist\user-sync.pex\.bootstrap\_pex\pex.py", line 347, in execute
  File "D:\Repositories\adobe\user-sync-fork\dist\user-sync.pex\.bootstrap\_pex\pex.py", line 90, in _activate
  File "D:\Repositories\adobe\user-sync-fork\dist\user-sync.pex\.bootstrap\_pex\environment.py", line 163, in activate
  File "D:\Repositories\adobe\user-sync-fork\dist\user-sync.pex\.bootstrap\_pex\environment.py", line 217, in _activate
  File "D:\Repositories\adobe\user-sync-fork\dist\user-sync.pex\.bootstrap\_pex\environment.py", line 152, in update_candidate_distributions
  File "D:\Repositories\adobe\user-sync-fork\dist\user-sync.pex\.bootstrap\_pex\environment.py", line 122, in load_internal_cache
  File "D:\Repositories\adobe\user-sync-fork\dist\user-sync.pex\.bootstrap\_pex\environment.py", line 109, in write_zipped_internal_cache
  File "D:\Repositories\adobe\user-sync-fork\dist\user-sync.pex\.bootstrap\_pex\util.py", line 178, in cache_distribution
  File "D:\Repositories\adobe\user-sync-fork\dist\user-sync.pex\.bootstrap\_pex\common.py", line 141, in safe_open
IOError: [Errno 2] No such file or directory: u'C:\\Users\\danimae.vossen\\.pex\\install\\pycryptodome-3.7.3-cp36-cp36m-win_amd64.whl.145f2de6f50a0f81798db664ba5586f1b1709d42.0d83d3f2328b4432bb0343bfac620753\\pycryptodome-3.7.3-cp36-cp36m-win_amd64.whl\\Crypto/SelfTest/Cipher/__pycache__/test_Blowfish.cpython-36.pyc'
